Workbook

Sheet Sheet1
A1: Sl No | B1: Title | C1: Deity | D1: Level | E1: Tempo | F1: Language | G1: Raga | H1: Shruti
A2: 1 | B2: Aneela Kumara Hanumantha | C2: anjaneya | D2: advanced | E2: medium | F2: sanskrit / hindi | G2: kanada, bageshri | H2: =VLOOKUP(LEFT(B2, 15) & "*", PMB!A:B, 2, FALSE) -> #N/A
A3: 2 | B3: Anjana Nanda Veeram Ashoka Vana Sancharam | C3: anjaneya | D3: intermediate | E3: fast | F3: sanskrit / hindi | G3: hamsanandi / sohini | H3: =VLOOKUP(LEFT(B3, 15) & "*", PMB!A:B, 2, FALSE) -> #N/A
A4: 3 | B4: Anjana Sutha Anjaneya | C4: anjaneya | D4: simple | E4: medium | F4: sanskrit / hindi | G4: maand | H4: =VLOOKUP(LEFT(B4, 15) & "*", PMB!A:B, 2, FALSE) -> #N/A
A5: 4 | B5: Anjaneya Hanumantha Veera | C5: anjaneya | F5: sanskrit / hindi | G5: mohanam / bhoop | H5: =VLOOKUP(LEFT(B5, 15) & "*", PMB!A:B, 2, FALSE) -> #N/A
A6: 5 | B6: Anjaneya Paahi Maam Hanumantha Paahi Maam | C6: anjaneya | F6: sanskrit / hindi | G6: hamsadhwani | H6: =VLOOKUP(LEFT(B6, 15) & "*", PMB!A:B, 2, FALSE) -> #N/A
A7: 6 | B7: Anjaneya Veera Hanumantha Shoora | C7: anjaneya | D7: simple | E7: fast | F7: sanskrit / hindi | G7: hamsadhwani | H7: =VLOOKUP(LEFT(B7, 15) & "*", PMB!A:B, 2, FALSE) -> #N/A
A8: 7 | B8: Apaara Mahima Gunavanta Anjaneya Balavanta | C8: anjaneya | D8: simple | E8: fast | F8: sanskrit / hindi | G8: shankarabharanam / bilawal | H8: =VLOOKUP(LEFT(B8, 15) & "*", PMB!A:B, 2, FALSE) -> #N/A
A9: 8 | B9: Hey Rama Dootha Hey Rama Bhaktha Hey Rama Daasa Namo Namo | C9: anjaneya | D9: intermediate | E9: medium fast | F9: sanskrit / hindi | G9: jaunpuri | H9: =VLOOKUP(LEFT(B9, 15) & "*", PMB!A:B, 2, FALSE) -> #N/A
A10: 9 | B10: Jai Jai Hanuman Jaya Hanuman (2) | C10: anjaneya | D10: intermediate | E10: medium fast | F10: sanskrit / hindi | G10: abheri / bhimpalas | H10: =VLOOKUP(LEFT(B10, 15) & "*", PMB!A:B, 2, FALSE) -> 2P
A11: 10 | B11: Jaya Anjaneya Jaya Rama Dootha Sharanam Prabho Sharanam | C11: anjaneya | D11: advanced | E11: fast | F11: sanskrit / hindi | G11: hamsanadam | H11: =VLOOKUP(LEFT(B11, 15) & "*", PMB!A:B, 2, FALSE) -> #N/A
A12: 11 | B12: Jaya Bajrang Jaya Balabheem Jaya Hanuman Jaya Bolo (2) | C12: anjaneya | F12: sanskrit / hindi | G12: kanada | H12: =VLOOKUP(LEFT(B12, 15) & "*", PMB!A:B, 2, FALSE) -> #N/A
A13: 12 | B13: Jaya Hanuman Jaya Hanuman (7) | C13: anjaneya | D13: simple | E13: fast | F13: sanskrit / hindi | G13: khamaj | H13: =VLOOKUP(LEFT(B13, 15) & "*", PMB!A:B, 2, FALSE) -> #N/A
A14: 13 | B14: Jaya Ho Jaya Ho Anjaneya | C14: anjaneya | D14: intermediate | E14: medium fast | F14: sanskrit / hindi | G14: brindavan sarang | H14: =VLOOKUP(LEFT(B14, 15) & "*", PMB!A:B, 2, FALSE) -> 3P
A15: 14 | B15: Jaya Jaya Pavana Kumara | C15: anjaneya | D15: simple | E15: fast | F15: sanskrit / hindi | G15: natabhairavi | H15: =VLOOKUP(LEFT(B15, 15) & "*", PMB!A:B, 2, FALSE) -> #N/A
A16: 15 | B16: Jaya Maruti Jaya Maruti Jaya Rama Dootha | C16: anjaneya | D16: intermediate | E16: medium fast | F16: sanskrit / hindi | G16: abheri / bhimpalas | H16: =VLOOKUP(LEFT(B16, 15) & "*", PMB!A:B, 2, FALSE) -> #N/A
A17: 16 | B17: Jaya Vijayee Bhava Jaya Vijayee Bhava | C17: anjaneya | D17: intermediate | E17: medium fast | F17: sanskrit / hindi | G17: desh | H17: =VLOOKUP(LEFT(B17, 15) & "*", PMB!A:B, 2, FALSE) -> #N/A
A18: 17 | B18: Mangala Murthy Maruti Raya Raghava Priya Jaya Hanuman | C18: anjaneya | D18: advanced | E18: medium | F18: sanskrit / hindi | G18: madhuvanti | H18: =VLOOKUP(LEFT(B18, 15) & "*", PMB!A:B, 2, FALSE) -> #N/A
A19: 18 | B19: Maruti Raya Mangala Naama | C19: anjaneya | F19: sanskrit / hindi | G19: hamsadhwani | H19: =VLOOKUP(LEFT(B19, 15) & "*", PMB!A:B, 2, FALSE) -> #N/A
A20: 19 | B20: Maruti Raya Namo Namo | C20: anjaneya | D20: intermediate | E20: fast | F20: sanskrit / hindi | G20: shuddha sarang | H20: =VLOOKUP(LEFT(B20, 15) & "*", PMB!A:B, 2, FALSE) -> #N/A
A21: 20 | B21: Pavana Sutha Hanuman Ki Jai | C21: anjaneya | D21: intermediate | E21: medium | F21: sanskrit / hindi | G21: yaman kalyan | H21: =VLOOKUP(LEFT(B21, 15) & "*", PMB!A:B, 2, FALSE) -> #N/A
A22: 21 | B22: Pavana Sutha Hanumantha | C22: anjaneya | F22: sanskrit / hindi | G22: sindhu bhairavi / bhairavi | H22: =VLOOKUP(LEFT(B22, 15) & "*", PMB!A:B, 2, FALSE) -> #N/A
A23: 22 | B23: Prabhu Ramachandra Ke Dootha Hanumantha Anjaneya | C23: anjaneya | D23: simple | E23: fast | F23: sanskrit / hindi | G23: kalyani / yaman | H23: =VLOOKUP(LEFT(B23, 15) & "*", PMB!A:B, 2, FALSE) -> 3P
A24: 23 | B24: Rama Bhaktha Hanumantha | C24: anjaneya | F24: sanskrit / hindi | G24: maand | H24: =VLOOKUP(LEFT(B24, 15) & "*", PMB!A:B, 2, FALSE) -> #N/A
A25: 24 | B25: Rama Dhyana Nirata Anjaneya | C25: anjaneya | D25: advanced | E25: fast | F25: sanskrit / hindi | G25: shivaranjani | H25: =VLOOKUP(LEFT(B25, 15) & "*", PMB!A:B, 2, FALSE) -> #N/A
A26: 25 | B26: Rama Lakshmana Janaki Jai Bolo Hanuman Ki | C26: anjaneya | D26: intermediate | E26: medium fast | F26: sanskrit / hindi, awadhi | G26: ~ shankarabharanam / bilawal | H26: =VLOOKUP(LEFT(B26, 15) & "*", PMB!A:B, 2, FALSE) -> 1P
A27: 26 | B27: Rama Lakshmana Janaki Jai Bolo Hanuman Ki (4) | C27: anjaneya | D27: intermediate | E27: fast | F27: sanskrit / hindi | G27: pilu, tilang | H27: =VLOOKUP(LEFT(B27, 15) & "*", PMB!A:B, 2, FALSE) -> 1P
A28: 27 | B28: Rama Lakshmana Janaki Jai Bolo Hanuman Ki | C28: anjaneya | D28: simple | E28: fast | F28: sanskrit / hindi | G28: shankarabharanam / bilawal | H28: =VLOOKUP(LEFT(B28, 15) & "*", PMB!A:B, 2, FALSE) -> 1P
A29: 28 | B29: Rama Naama Smaranam Sada Mokshanandakaram | C29: rama, krishna, sai, anjaneya | F29: sanskrit / hindi | G29: dwijavanti / jaijaivanti | H29: =VLOOKUP(LEFT(B29, 15) & "*", PMB!A:B, 2, FALSE) -> #N/A
A30: 29 | B30: Sita Rakshaka Rama Dootha | C30: anjaneya | D30: intermediate | E30: fast | F30: sanskrit / hindi | G30: madhyamavati / madhmad sarang | H30: =VLOOKUP(LEFT(B30, 15) & "*", PMB!A:B, 2, FALSE) -> #N/A
A31: 30 | B31: Sita Ramachandra Ki Jai Jai Bolo | C31: anjaneya | D31: simple | E31: medium fast | F31: sanskrit / hindi | G31: surya | H31: =VLOOKUP(LEFT(B31, 15) & "*", PMB!A:B, 2, FALSE) -> #N/A
A32: 31 | B32: Sri Rama Daasa Rama Dootha Jai Bolo Hanuman Ki | C32: anjaneya | D32: intermediate | E32: fast | F32: sanskrit / hindi | G32: chandrakauns | H32: =VLOOKUP(LEFT(B32, 15) & "*", PMB!A:B, 2, FALSE) -> #N/A
A33: 32 | B33: Sri Rama Dootha Jaya Hanuman | C33: anjaneya | D33: intermediate | E33: medium fast | F33: sanskrit / hindi | G33: karaharapriya / kafi | H33: =VLOOKUP(LEFT(B33, 15) & "*", PMB!A:B, 2, FALSE) -> #N/A
A34: 33 | B34: Vayu Kumara Vanara Veera | C34: anjaneya | D34: simple | E34: medium slow | F34: sanskrit / hindi | G34: khamaj | H34: =VLOOKUP(LEFT(B34, 15) & "*", PMB!A:B, 2, FALSE) -> 3P
A35: 34 | B35: Veera Dheera Shoora Hanuman Ki Jai | C35: anjaneya | D35: intermediate | E35: medium fast | F35: sanskrit / hindi | G35: vibhas | H35: =VLOOKUP(LEFT(B35, 15) & "*", PMB!A:B, 2, FALSE) -> 3P
A36: 35 | B36: Veera Hanumana Ati Balawana Ram Naam Rasiyarey | C36: anjaneya | D36: simple | E36: medium fast | F36: sanskrit / hindi | G36: shankarabharanam / bilawal, khamaj | H36: =VLOOKUP(LEFT(B36, 15) & "*", PMB!A:B, 2, FALSE) -> #N/A
A37: 36 | B37: Veera Hanumathey Namo Namo | C37: anjaneya | F37: sanskrit / hindi | G37: kanada | H37: =VLOOKUP(LEFT(B37, 15) & "*", PMB!A:B, 2, FALSE) -> #N/A
A38: 37 | B38: Veera Maruti Gambhira Maruti | C38: anjaneya | D38: intermediate | E38: medium fast | F38: sanskrit / hindi | G38: sindhu bhairavi / bhairavi | H38: =VLOOKUP(LEFT(B38, 15) & "*", PMB!A:B, 2, FALSE) -> #N/A
A39: 38 | B39: (Namo) Devi Durga Janani Devi Amba Bhavani | C39: devi | D39: advanced | E39: medium | F39: sanskrit / hindi | G39: ~ hamsadhwani | H39: =VLOOKUP(LEFT(B39, 15) & "*", PMB!A:B, 2, FALSE) -> #N/A
A40: 39 | B40: Abhaya Pradayini Ananda Roopini | C40: devi | D40: advanced | E40: medium | F40: sanskrit / hindi | G40: kapi | H40: =VLOOKUP(LEFT(B40, 15) & "*", PMB!A:B, 2, FALSE) -> #N/A
...

Sheet PMB
A1: Bhajan | B1: Sruthi | C1: Verify
A2: Aao Aao Hey Bhagawan | B2: 1.5P | C2: =COUNTIF(Sheet1!B:B, "*" & LEFT(A2, 12) & "*") -> 1
A3: Aao Aao Nandalala | B3: 2M | C3: =COUNTIF(Sheet1!B:B, "*" & LEFT(A3, 12) & "*") -> 1
A4: Aao Aao Sai Pyaare | B4: 1M | C4: =COUNTIF(Sheet1!B:B, "*" & LEFT(A4, 12) & "*") -> 3
A5: Aao Prabho Aao Sai Bhagawan | B5: 2P | C5: =COUNTIF(Sheet1!B:B, "*" & LEFT(A5, 12) & "*") -> 0
A6: Aao Pyare Nayana Hamare | B6: 7P | C6: =COUNTIF(Sheet1!B:B, "*" & LEFT(A6, 12) & "*") -> 0
A7: Aao Sai Gopal | B7: 1.5P | C7: =COUNTIF(Sheet1!B:B, "*" & LEFT(A7, 12) & "*") -> 1
A8: Adi Narayana Sai Narayana | B8: 2.5M | C8: =COUNTIF(Sheet1!B:B, "*" & LEFT(A8, 12) & "*") -> 1
A9: Ajanu Bahum Aravinda Netram | B9: 1.5P | C9: =COUNTIF(Sheet1!B:B, "*" & LEFT(A9, 12) & "*") -> 1
A10: Akhanda Jyoti Jalao | B10: 1.5M | C10: =COUNTIF(Sheet1!B:B, "*" & LEFT(A10, 12) & "*") -> 1
A11: Akhila Jagata Ke Data Sai | B11: 1.5M | C11: =COUNTIF(Sheet1!B:B, "*" & LEFT(A11, 12) & "*") -> 1
A12: Alakh Niranjana Bhava Bhaya Bhanjana | B12: 7P | C12: =COUNTIF(Sheet1!B:B, "*" & LEFT(A12, 12) & "*") -> 4
A13: Allah Allah Karo Pukar | B13: 2M | C13: =COUNTIF(Sheet1!B:B, "*" & LEFT(A13, 12) & "*") -> 2
... A1003: Yugavatara Radhe Shyam | B1003: 1P | C1003: =COUNTIF(Sheet1!B:B, "*" & LEFT(A1003, 12) & "*") -> 0
